Workbook

Sheet Total
B1: 2023 | C1: 2024 | D1: 2025
A2: Total kørselsgodtgørelse | B2: =SUM('Kørselsgodtgørelse okt 2023 '!K13,'Kørselsgodtgørelse Nov 2023'!K13,'Kørselsgodtgørelse Dec 2023'!K13) -> 4565.52 | C2: =SUM('Kørselsgodtgørelse Jan 2024'!K13+'Kørselsgodtgørelse Feb 2024'!K13+'Kørselsgodtgørelse Marts 2024'!K13+'Kørselsgodtgørelse April 2024'!K13+'Kørselsgodtgørelse April 2024'!K13+'Kørselsgodtgørelse Maj 2024'!K13+'Kørselsgodtgørelse Juni 2024'!K13+'Kørselsgodtgørelse Juli 2024'!K13+'Kørselsgodtgørelse Aug 2024'!K13+'Kørselsgodtgørelse Sept 2024'!K13+'Kørselsgodtgørelse Okt 2024'!K13+'Kørselsgodtgørelse Nov 2024'!K13) -> 27458.55
C10: marts til nov | D10: =SUM('Kørselsgodtgørelse Marts 2024'!K13+'Kørselsgodtgørelse April 2024'!K13+'Kørselsgodtgørelse April 2024'!K13+'Kørselsgodtgørelse Maj 2024'!K13+'Kørselsgodtgørelse Juni 2024'!K13+'Kørselsgodtgørelse Juli 2024'!K13+'Kørselsgodtgørelse Aug 2024'!K13+'Kørselsgodtgørelse Sept 2024'!K13+'Kørselsgodtgørelse Okt 2024'!K13+'Kørselsgodtgørelse Nov 2024'!K13) -> 19704.21
C11: dec tom. januar | D11: =SUM('Kørselsgodtgørelse Dec 2024'!K13)+('Kørselsgodtgørelse Jan 2025'!K13) -> 6791.48
A16: ='Kørselsgodtgørelse Marts 2024'!K11+'Kørselsgodtgørelse April 2024'!K11+'Kørselsgodtgørelse Maj 2024'!K11+'Kørselsgodtgørelse Juni 2024'!K11+'Kørselsgodtgørelse Juli 2024'!K11+'Kørselsgodtgørelse Aug 2024'!K11+'Kørselsgodtgørelse Sept 2024'!K11+'Kørselsgodtgørelse Okt 2024'!K11+'Kørselsgodtgørelse Nov 2024'!K11+'Kørselsgodtgørelse Dec 2024'!K11+'Kørselsgodtgørelse Jan 2025'!K11 -> 6347

Sheet Kørselsgodtgørelse okt 2023 
B7: Skabelon til kørselsgodtgørelse er fra Dinero Regnskabsprogram
B9: Periode | C9: Oktober | H9: Medarbejderens navn | J9: Sven Arnarsson
B10: Nummerplade | C10: DE 58647 | H10: Medarbejderens CPR-nummer | J10: 0411883183
J11: Samlet km | K11: =SUM(L18:L21) -> 210
J12: Sats | K12: 3,73 kr
J13: Total | K13: 783.3
B14: Kørselsregnskab
B16: Dato (skal altid udfyldes) | C16: Beskrivelse (udfyld ved erhverv) | D16: Formålet for kørsel (sæt 1) | F16: Fra (udfyld ved erhverv) | H16: Til (udfyld ved erhverv) | J16: Kilometertæller | L16: Kilometer
D17: Erhverv | E17: Privat | F17: Vejnavn og nr. | G17: Postnummer | H17: Vejnavn og nr. | I17: Postnummer | J17: Frem | K17: Tilbage | L17: Erhverv | M17: Privat
B18: 45224 | C18: elbiil.dk - Intro møde | D18: 1 | F18: Platanvej 7 | G18: 2791 | H18: Klausdalsbrovej 601 | I18: 2750 | J18: 39 | K18: 39 | L18: =SUM(J18,K18) -> 78
B19: 45225 | C19: Digital Wasabi - møde | D19: 1 | F19: Platanvej 7 | G19: 2791 | H19: Islands Brygge 79b | I19: 2300 | J19: 15 | K19: 15 | L19: =SUM(J19,K19) -> 30
B20: 45228 | C20: eCar Expo - messe | D20: 1 | F20: Platanvej 7 | G20: 2791 | H20: Center Blvd. 5 | I20: 2300 | J20: 12 | K20: 12 | L20: =SUM(J20,K20) -> 24
B21: 45230 | C21: elbiil.dk - workshop møde | D21: 1 | F21: Platanvej 7 | G21: 2791 | H21: Klausdalsbrovej 601 | I21: 2750 | J21: 39 | K21: 39 | L21: =SUM(J21,K21) -> 78
L88: =(K88-J88)*D88 -> 0 | M88: =(K88-J88)*E88 -> 0
L89: =(K89-J89)*D89 -> 0 | M89: =(K89-J89)*E89 -> 0
C91: (Erhvervsmæssigt) antal kørte kilometer før denne periode i indeværende år
H92: 0 | I92: Dette skal indtastes jf. kørselsregnskab forrige måned i indeværende år
C94: (Erhvervsmæssigt) Antal kørte kilometer i denne måned | H94: =SUM(L18:L89) -> 210 | I94: Beregnes automatisk
C96: Sum antal kørte kilometer erhvervsmæssigt hele året (inkl. denne måned) | H96: =H92+H94 -> 210 | I96: Beregnes automatisk
C98: Kørte kilometer i denne måned (hvor samlet sum af kørte kilometer i året er under 20.000) | H98: =IF(H96<=20000,H94,IF(H92>20000,0,20000-H92)) -> 210 | I98: Beregnes automatisk
C100: Kørte kilometer i denne måned (hvor samlet sum af kørte kilometer i året er over 20.000) | H100: =IF(H96>20000,H96-H92-H98,0) -> 0 | I100: Beregnes automatisk
C102: Fradrag/ godtgørelse pr. km. | D102: 3.73 | E102: (Kørsel til og med 20.000 km. I året, jf. Skattestyrelsens satser for befordringsgodtgørelse i 2021)
D103: 2.19 | E103: (Kørsel udover 20.000 km. I året, jf. Skattestyrelsens sats for befordringsgodtgørelse i 2021)
C105: Kørselsfradrag/kørselsgodtgørelse i perioden: | G105: =(H98*D102)+(H100*D103) -> 783.3 | I105: Beregnes automatisk
C107: Godkendt af (underskrift eller stempel)
C109: Dato

Sheet Kørselsgodtgørelse Nov 2023
B7: Skabelon til kørselsgodtgørelse er fra Dinero Regnskabsprogram
B9: Periode | C9: Nov | H9: Medarbejderens navn | J9: Sven Arnarsson
B10: Nummerplade | C10: DE 58647 | H10: Medarbejderens CPR-nummer | J10: 0411883183
J11: Samlet km | K11: =SUM(L18:L30) -> 624
J12: Sats | K12: 3,73 kr
J13: Total | K13: =SUM(K11)*3.73 -> 2327.52
B14: Kørselsregnskab
B16: Dato (skal altid udfyldes) | C16: Beskrivelse (udfyld ved erhverv) | D16: Formålet for kørsel (sæt 1) | F16: Fra (udfyld ved erhverv) | H16: Til (udfyld ved erhverv) | J16: Kilometertæller | L16: Kilometer
D17: Erhverv | E17: Privat | F17: Vejnavn og nr. | G17: Postnummer | H17: Vejnavn og nr. | I17: Postnummer | J17: Frem | K17: Tilbage | L17: Erhverv | M17: Privat
B18: 45238 | C18: elbiil.dk - arbejde kontor | D18: 1 | F18: Platanvej 7 | G18: 2791 | H18: Klausdalsbrovej 601 | I18: 2750 | J18: 39 | K18: 39 | L18: =SUM(J18,K18) -> 78
B19: 45239 | C19: elbiil.dk - arbejde kontor | D19: 1 | F19: Platanvej 7 | G19: 2791 | H19: Klausdalsbrovej 601 | I19: 2750 | J19: 39 | K19: 39 | L19: =SUM(J19,K19) -> 78
B20: 45245 | C20: elbiil.dk - arbejde kontor | D20: 1 | F20: Platanvej 7 | G20: 2791 | H20: Klausdalsbrovej 601 | I20: 2750 | J20: 39 | K20: 39 | L20: =SUM(J20,K20) -> 78
B21: 45246 | C21: elbiil.dk - arbejde kontor | D21: 1 | F21: Platanvej 7 | G21: 2791 | H21: Klausdalsbrovej 601 | I21: 2750 | J21: 39 | K21: 39 | L21: =SUM(J21,K21) -> 78
B22: 45252 | C22: elbiil.dk - arbejde kontor | D22: 1 | F22: Platanvej 7 | G22: 2791 | H22: Klausdalsbrovej 601 | I22: 2750 | J22: 39 | K22: 39 | L22: =SUM(J22,K22) -> 78
B23: 45253 | C23: elbiil.dk - arbejde kontor | D23: 1 | F23: Platanvej 7 | G23: 2791 | H23: Klausdalsbrovej 601 | I23: 2750 | J23: 39 | K23: 39 | L23: =SUM(J23,K23) -> 78
B24: 45259 | C24: elbiil.dk - arbejde kontor | D24: 1 | F24: Platanvej 7 | G24: 2791 | H24: Klausdalsbrovej 601 | I24: 2750 | J24: 39 | K24: 39 | L24: =SUM(J24,K24) -> 78
B25: 45260 | C25: elbiil.dk - arbejde kontor | D25: 1 | F25: Platanvej 7 | G25: 2791 | H25: Klausdalsbrovej 601 | I25: 2750 | J25: 39 | K25: 39 | L25: =SUM(J25,K25) -> 78
L88: =(K88-J88)*D88 -> 0 | M88: =(K88-J88)*E88 -> 0
L89: =(K89-J89)*D89 -> 0 | M89: =(K89-J89)*E89 -> 0
C91: (Erhvervsmæssigt) antal kørte kilometer før denne periode i indeværende år
H92: 0 | I92: Dette skal indtastes jf. kørselsregnskab forrige måned i indeværende år
C94: (Erhvervsmæssigt) Antal kørte kilometer i denne måned | H94: =SUM(L18:L89) -> 624 | I94: Beregnes automatisk
C96: Sum antal kørte kilometer erhvervsmæssigt hele året (inkl. denne måned) | H96: =H92+H94 -> 624 | I96: Beregnes automatisk
C98: Kørte kilometer i denne måned (hvor samlet sum af kørte kilometer i året er under 20.000) | H98: =IF(H96<=20000,H94,IF(H92>20000,0,20000-H92)) -> 624 | I98: Beregnes automatisk
C100: Kørte kilometer i denne måned (hvor samlet sum af kørte kilometer i året er over 20.000) | H100: =IF(H96>20000,H96-H92-H98,0) -> 0 | I100: Beregnes automatisk
C102: Fradrag/ godtgørelse pr. km. | D102: 3.73 | E102: (Kørsel til og med 20.000 km. I året, jf. Skattestyrelsens satser for befordringsgodtgørelse i 2021)
D103: 2.19 | E103: (Kørsel udover 20.000 km. I året, jf. Skattestyrelsens sats for befordringsgodtgørelse i 2021)
C105: Kørselsfradrag/kørselsgodtgørelse i perioden: | G105: =(H98*D102)+(H100*D103) -> 2327.52 | I105: Beregnes automatisk
C107: Godkendt af (underskrift eller stempel)
C109: Dato

Sheet Kørselsgodtgørelse Dec 2023
B7: Skabelon til kørselsgodtgørelse er fra Dinero Regnskabsprogram
B9: Periode | C9: 45261 | H9: Medarbejderens navn | J9: Sven Arnarsson
B10: Nummerplade | C10: DE 58647 | H10: Medarbejderens CPR-nummer | J10: 0411883183
J11: Samlet km | K11: =SUM(L18:L22) -> 390
J12: Sats | K12: 3,73 kr
J13: Total | K13: =SUM(K11)*3.73 -> 1454.7
B14: Kørselsregnskab
B16: Dato (skal altid udfyldes) | C16: Beskrivelse (udfyld ved erhverv) | D16: Formålet for kørsel (sæt 1) | F16: Fra (udfyld ved erhverv) | H16: Til (udfyld ved erhverv) | J16: Kilometertæller | L16: Kilometer
D17: Erhverv | E17: Privat | F17: Vejnavn og nr. | G17: Postnummer | H17: Vejnavn og nr. | I17: Postnummer | J17: Frem | K17: Tilbage | L17: Erhverv | M17: Privat
B18: 45266 | C18: elbiil.dk - arbejde kontor | D18: 1 | F18: Platanvej 7 | G18: 2791 | H18: Klausdalsbrovej 601 | I18: 2750 | J18: 39 | K18: 39 | L18: =SUM(J18,K18) -> 78
B19: 45267 | C19: elbiil.dk - arbejde kontor | D19: 1 | F19: Platanvej 7 | G19: 2791 | H19: Klausdalsbrovej 601 | I19: 2750 | J19: 39 | K19: 39 | L19: =SUM(J19,K19) -> 78
B20: 45273 | C20: elbiil.dk - arbejde kontor | D20: 1 | F20: Platanvej 7 | G20: 2791 | H20: Klausdalsbrovej 601 | I20: 2750 | J20: 39 | K20: 39 | L20: =SUM(J20,K20) -> 78
B21: 45274 | C21: elbiil.dk - arbejde kontor | D21: 1 | F21: Platanvej 7 | G21: 2791 | H21: Klausdalsbrovej 601 | I21: 2750 | J21: 39 | K21: 39 | L21: =SUM(J21,K21) -> 78
B22: 45280 | C22: elbiil.dk - arbejde kontor | D22: 1 | F22: Platanvej 7 | G22: 2791 | H22: Klausdalsbrovej 601 | I22: 2750 | J22: 39 | K22: 39 | L22: =SUM(J22,K22) -> 78
B23: 45281 | C23: elbiil.dk - arbejde kontor | D23: 1 | F23: Platanvej 7 | G23: 2791 | H23: Klausdalsbrovej 601 | I23: 2750 | J23: 39 | K23: 39 | L23: =SUM(J23,K23) -> 78
L80: =(K80-J80)*D80 -> 0 | M80: =(K80-J80)*E80 -> 0
L81: =(K81-J81)*D81 -> 0 | M81: =(K81-J81)*E81 -> 0
C83: (Erhvervsmæssigt) antal kørte kilometer før denne periode i indeværende år
H84: 0 | I84: Dette skal indtastes jf. kørselsregnskab forrige måned i indeværende år
C86: (Erhvervsmæssigt) Antal kørte kilometer i denne måned | H86: =SUM(L18:L81) -> 468 | I86: Beregnes automatisk
C88: Sum antal kørte kilometer erhvervsmæssigt hele året (inkl. denne måned) | H88: =H84+H86 -> 468 | I88: Beregnes automatisk
C90: Kørte kilometer i denne måned (hvor samlet sum af kørte kilometer i året er under 20.000) | H90: =IF(H88<=20000,H86,IF(H84>20000,0,20000-H84)) -> 468 | I90: Beregnes automatisk
C92: Kørte kilometer i denne måned (hvor samlet sum af kørte kilometer i året er over 20.000) | H92: =IF(H88>20000,H88-H84-H90,0) -> 0 | I92: Beregnes automatisk
C94: Fradrag/ godtgørelse pr. km. | D94: 3.73 | E94: (Kørsel til og med 20.000 km. I året, jf. Skattestyrelsens satser for befordringsgodtgørelse i 2021)
D95: 2.19 | E95: (Kørsel udover 20.000 km. I året, jf. Skattestyrelsens sats for befordringsgodtgørelse i 2021)
C97: Kørselsfradrag/kørselsgodtgørelse i perioden: | G97: =(H90*D94)+(H92*D95) -> 1745.64 | I97: Beregnes automatisk
C99: Godkendt af (underskrift eller stempel)
C101: Dato

Sheet Kørselsgodtgørelse Jan 2024
B7: Skabelon til kørselsgodtgørelse er fra Dinero Regnskabsprogram
B9: Periode | C9: 45292 | H9: Medarbejderens navn | J9: Sven Arnarsson
B10: Nummerplade | C10: DE 58647 | H10: Medarbejderens CPR-nummer | J10: 0411883183
J11: Samlet km | K11: =SUM(L18:L29) -> 856
J12: Sats | K12: 3.79
B13: https://dinero.dk/support/kilometergodtgoerelse/ | J13: Total | K13: =SUM(K11*K12) -> 3244.24
B14: Kørselsregnskab
B16: Dato (skal altid udfyldes) | C16: Beskrivelse (udfyld ved erhverv) | D16: Formålet for kørsel (sæt 1) | F16: Fra (udfyld ved erhverv) | H16: Til (udfyld ved erhverv) | J16: Kilometertæller | L16: Kilometer
D17: Erhverv | E17: Privat | F17: Vejnavn og nr. | G17: Postnummer | H17: Vejnavn og nr. | I17: Postnummer | J17: Frem | K17: Tilbage | L17: Erhverv | M17: Privat
B18: 45294 | C18: elbiil.dk - arbejde kontor | D18: 1 | F18: Platanvej 7 | G18: 2791 | H18: Klausdalsbrovej 601 | I18: 2750 | J18: 39 | K18: 39 | L18: =SUM(J18,K18) -> 78
B19: 45295 | C19: elbiil.dk - arbejde kontor | D19: 1 | F19: Platanvej 7 | G19: 2791 | H19: Klausdalsbrovej 601 | I19: 2750 | J19: 39 | K19: 39 | L19: =SUM(J19,K19) -> 78
B20: 45301 | C20: elbiil.dk - arbejde kontor | D20: 1 | F20: Platanvej 7 | G20: 2791 | H20: Klausdalsbrovej 601 | I20: 2750 | J20: 39 | K20: 39 | L20: =SUM(J20,K20) -> 78
B21: 45302 | C21: elbiil.dk - arbejde kontor | D21: 1 | F21: Platanvej 7 | G21: 2791 | H21: Klausdalsbrovej 601 | I21: 2750 | J21: 39 | K21: 39 | L21: =SUM(J21,K21) -> 78
B22: 16/01/24 | C22: Møde med potentiel kunde | D22: 1 | F22: Platanvej | G22: 2791 | H22: Fuglesangsvej 11 | I22: 1962 | J22: 19 | K22: 19 | L22: 38
B23: 45308 | C23: elbiil.dk - arbejde kontor | D23: 1 | F23: Platanvej 7 | G23: 2791 | H23: Klausdalsbrovej 601 | I23: 2750 | J23: 39 | K23: 39 | L23: =SUM(J23,K23) -> 78
B24: 45310 | C24: elbiil.dk - arbejde kontor | D24: 1 | F24: Platanvej 7 | G24: 2791 | H24: Klausdalsbrovej 601 | I24: 2750 | J24: 39 | K24: 39 | L24: =SUM(J24,K24) -> 78
B25: 45315 | C25: elbiil.dk - arbejde kontor | D25: 1 | F25: Platanvej 7 | G25: 2791 | H25: Klausdalsbrovej 601 | I25: 2750 | J25: 39 | K25: 39 | L25: =SUM(J25,K25) -> 78
B26: 45316 | C26: elbiil.dk - arbejde kontor | D26: 1 | F26: Platanvej 7 | G26: 2791 | H26: Klausdalsbrovej 601 | I26: 2750 | J26: 39 | K26: 39 | L26: =SUM(J26,K26) -> 78
B27: 45320 | C27: elbiil.dk - arbejde kontor | D27: 1 | F27: Platanvej 7 | G27: 2791 | H27: Klausdalsbrovej 601 | I27: 2750 | J27: 39 | K27: 39 | L27: =SUM(J27,K27) -> 78
C28: Workshop for 2030 | F28: Platanvej 8 | G28: 2791 | H28: Fuglevangsvej 11, 1962 Frederiksberg | I28: 1962 | J28: 19 | K28: 19 | L28: =SUM(J28,K28) -> 38
B29: 45322 | C29: elbiil.dk - arbejde kontor | D29: 1 | F29: Platanvej 8 | G29: 2792 | H29: Klausdalsbrovej 602 | I29: 2750 | J29: 39 | K29: 39 | L29: =SUM(J29,K29) -> 78
L76: =(K76-J76)*D76 -> 0 | M76: =(K76-J76)*E76 -> 0
L77: =(K77-J77)*D77 -> 0 | M77: =(K77-J77)*E77 -> 0
C79: (Erhvervsmæssigt) antal kørte kilometer før denne periode i indeværende år
H80: 0 | I80: Dette skal indtastes jf. kørselsregnskab forrige måned i indeværende år
C82: (Erhvervsmæssigt) Antal kørte kilometer i denne måned | H82: =SUM(L18:L77) -> 856 | I82: Beregnes automatisk
C84: Sum antal kørte kilometer erhvervsmæssigt hele året (inkl. denne måned) | H84: =H80+H82 -> 856 | I84: Beregnes automatisk
C86: Kørte kilometer i denne måned (hvor samlet sum af kørte kilometer i året er under 20.000) | H86: =IF(H84<=20000,H82,IF(H80>20000,0,20000-H80)) -> 856 | I86: Beregnes automatisk
C88: Kørte kilometer i denne måned (hvor samlet sum af kørte kilometer i året er over 20.000) | H88: =IF(H84>20000,H84-H80-H86,0) -> 0 | I88: Beregnes automatisk
C90: Fradrag/ godtgørelse pr. km. | D90: 3.79 | E90: (Kørsel til og med 20.000 km. I året, jf. Skattestyrelsens satser for befordringsgodtgørelse i 2021)
D91: 2.23 | E91: (Kørsel udover 20.000 km. I året, jf. Skattestyrelsens sats for befordringsgodtgørelse i 2021)
C93: Kørselsfradrag/kørselsgodtgørelse i perioden: | G93: =(H86*D90)+(H88*D91) -> 3244.24 | I93: Beregnes automatisk
C95: Godkendt af (underskrift eller stempel)
C97: Dato
F120: https://dinero.dk/support/kilometergodtgoerelse/

Sheet Kørselsgodtgørelse Feb 2024
B7: Skabelon til kørselsgodtgørelse er fra Dinero Regnskabsprogram
B9: Periode | C9: 45323 | H9: Medarbejderens navn | J9: Sven Arnarsson
B10: Nummerplade | C10: CM73464 | H10: Medarbejderens CPR-nummer | J10: 0411883183
J11: Samlet km | K11: =SUM(L18:L29) -> 1190
J12: Sats | K12: 3.79
A13: https://dinero.dk/support/kilometergodtgoerelse/ | J13: Total | K13: =SUM(K11*K12) -> 4510.1
B14: Kørselsregnskab
B16: Dato (skal altid udfyldes) | C16: Beskrivelse (udfyld ved erhverv) | D16: Formålet for kørsel (sæt 1) | F16: Fra (udfyld ved erhverv) | H16: Til (udfyld ved erhverv) | J16: Kilometertæller | L16: Kilometer
D17: Erhverv | E17: Privat | F17: Vejnavn og nr. | G17: Postnummer | H17: Vejnavn og nr. | I17: Postnummer | J17: Frem | K17: Tilbage | L17: Erhverv | M17: Privat
B18: 45323 | C18: elbiil.dk - arbejde kontor | D18: 1 | F18: Platanvej 7 | G18: 2791 | H18: Klausdalsbrovej 601 | I18: 2750 | J18: 39 | K18: 39 | L18: =SUM(J18,K18) -> 78
B19: 45324 | C19: FlexeCharge -Workshop | D19: 1 | F19: Platanvej 7 | G19: 2791 | H19: Fruebjergvej 3 | I19: 2100 | J19: 23 | K19: 23 | L19: =SUM(J19,K19) -> 46
B20: 45330 | C20: elbiil.dk - arbejde kontor | D20: 1 | F20: Platanvej 7 | G20: 2791 | H20: Klausdalsbrovej 601 | I20: 2750 | J20: 39 | K20: 39 | L20: =SUM(J20,K20) -> 78
B21: 45331 | C21: elbiil.dk - arbejde kontor | D21: 1 | F21: Platanvej 7 | G21: 2791 | H21: Klausdalsbrovej 601 | I21: 2750 | J21: 39 | K21: 39 | L21: =SUM(J21,K21) -> 78
B22: 45337 | C22: elbiil.dk - arbejde kontor | D22: 1 | F22: Platanvej 7 | G22: 2791 | H22: Klausdalsbrovej 601 | I22: 2750 | J22: 39 | K22: 39 | L22: =SUM(J22,K22) -> 78
B23: 45338 | C23: elbiil.dk - arbejde kontor | D23: 1 | F23: Platanvej 7 | G23: 2791 | H23: Klausdalsbrovej 601 | I23: 2750 | J23: 39 | K23: 39 | L23: =SUM(J23,K23) -> 78
B24: 45342 | C24: Første møde m. Waily | D24: 1 | F24: Platanvej 7 | G24: 2791 | H24: Frederiksborggade 14 | I24: 1360 | J24: 20 | K24: 20 | L24: =SUM(J24,K24) -> 40
B25: 45343 | C25: elbiil.dk - arbejde kontor | D25: 1 | F25: Platanvej 7 | G25: 2791 | H25: Klausdalsbrovej 601 | I25: 2750 | J25: 39 | K25: 39 | L25: =SUM(J25,K25) -> 78
B26: 45344 | C26: elbiil.dk - arbejde kontor | D26: 1 | F26: Platanvej 7 | G26: 2791 | H26: Klausdalsbrovej 601 | I26: 2750 | J26: 39 | K26: 39 | L26: =SUM(J26,K26) -> 78
B27: 45351 | C27: elbiil.dk - arbejde kontor | D27: 1 | F27: Platanvej 7 | G27: 2791 | H27: Klausdalsbrovej 601 | I27: 2750 | J27: 39 | K27: 39 | L27: =SUM(J27,K27) -> 78
B28: 45414 | C28: Møde med potentiel kunde i Kolding | D28: 1 | F28: Platanvej 7 | G28: 2791 | H28: Kolding, storcenter | I28: 6000 | J28: 240 | K28: 240 | L28: =SUM(J28,K28) -> 480
L76: =(K76-J76)*D76 -> 0 | M76: =(K76-J76)*E76 -> 0
L77: =(K77-J77)*D77 -> 0 | M77: =(K77-J77)*E77 -> 0
C79: (Erhvervsmæssigt) antal kørte kilometer før denne periode i indeværende år
H80: 0 | I80: Dette skal indtastes jf. kørselsregnskab forrige måned i indeværende år
C82: (Erhvervsmæssigt) Antal kørte kilometer i denne måned | H82: =SUM(L18:L77) -> 1190 | I82: Beregnes automatisk
C84: Sum antal kørte kilometer erhvervsmæssigt hele året (inkl. denne måned) | H84: =H80+H82 -> 1190 | I84: Beregnes automatisk
C86: Kørte kilometer i denne måned (hvor samlet sum af kørte kilometer i året er under 20.000) | H86: =IF(H84<=20000,H82,IF(H80>20000,0,20000-H80)) -> 1190 | I86: Beregnes automatisk
C88: Kørte kilometer i denne måned (hvor samlet sum af kørte kilometer i året er over 20.000) | H88: =IF(H84>20000,H84-H80-H86,0) -> 0 | I88: Beregnes automatisk
C90: Fradrag/ godtgørelse pr. km. | D90: 3.79 | E90: (Kørsel til og med 20.000 km. I året, jf. Skattestyrelsens satser for befordringsgodtgørelse i 2021)
D91: 2.23 | E91: (Kørsel udover 20.000 km. I året, jf. Skattestyrelsens sats for befordringsgodtgørelse i 2021)
C93: Kørselsfradrag/kørselsgodtgørelse i perioden: | G93: =(H86*D90)+(H88*D91) -> 4510.1 | I93: Beregnes automatisk
C95: Godkendt af (underskrift eller stempel)
C97: Dato

Sheet Kørselsgodtgørelse Marts 2024
B7: Skabelon til kørselsgodtgørelse er fra Dinero Regnskabsprogram
B9: Periode | C9: 45352 | H9: Medarbejderens navn | J9: Sven Arnarsson
B10: Nummerplade | C10: CM73464 | H10: Medarbejderens CPR-nummer | J10: 0411883183
J11: Samlet km | K11: =SUM(L18:L31) -> 650
J12: Sats | K12: 3.79
A13: https://dinero.dk/support/kilometergodtgoerelse/ | J13: Total | K13: =SUM(K11*K12) -> 2463.5
B14: Kørselsregnskab
B16: Dato (skal altid udfyldes) | C16: Beskrivelse (udfyld ved erhverv) | D16: Formålet for kørsel (sæt 1) | F16: Fra (udfyld ved erhverv) | H16: Til (udfyld ved erhverv) | J16: Kilometertæller
D17: Erhverv | E17: Privat | F17: Vejnavn og nr. | G17: Postnummer | H17: Vejnavn og nr. | I17: Postnummer | J17: Frem | K17: Tilbage | L17: Erhverv | M17: Privat
B18: 45352 | C18: elbiil.dk - arbejde kontor | D18: 1 | F18: Platanvej 7 | G18: 2791 | H18: Klausdalsbrovej 601 | I18: 2750 | J18: 39 | K18: 39 | L18: =SUM(J18:K18) -> 78
B19: 45358 | C19: elbiil.dk - arbejde kontor | D19: 1 | F19: Platanvej 7 | G19: 2791 | H19: Klausdalsbrovej 601 | I19: 2750 | J19: 39 | K19: 39 | L19: =SUM(J19:K19) -> 78
B20: 45364 | C20: elbiil.dk - arbejde kontor | D20: 1 | F20: Platanvej 7 | G20: 2791 | H20: Klausdalsbrovej 601 | I20: 2750 | J20: 39 | K20: 39 | L20: =SUM(J20:K20) -> 78
B21: 45370 | C21: elbiil.dk - arbejde kontor | D21: 1 | F21: Platanvej 7 | G21: 2791 | H21: Klausdalsbrovej 601 | I21: 2750 | J21: 39 | K21: 39 | L21: =SUM(J21:K21) -> 78
B22: 45376 | C22: elbiil.dk - arbejde kontor | D22: 1 | F22: Platanvej 7 | G22: 2791 | H22: Klausdalsbrovej 601 | I22: 2750 | J22: 39 | K22: 39 | L22: =SUM(J22:K22) -> 78
B23: 45382 | C23: Green & Clean - intro møde | D23: 1 | F23: Platanvej 7 | G23: 2791 | H23: c/o Linus Johannes Bruun Knudsen, Oscar Pettifords Vej 15 3. th., 2450 | I23: 2450 | J23: 13 | K23: 13 | L23: =SUM(J23:K23) -> 26
B24: 45388 | C24: elbiil.dk - arbejde kontor | D24: 1 | F24: Platanvej 7 | G24: 2791 | H24: Klausdalsbrovej 601 | I24: 2750 | J24: 39 | K24: 39 | L24: =SUM(J24:K24) -> 78
B25: 45394 | C25: elbiil.dk - arbejde kontor | D25: 1 | F25: Platanvej 7 | G25: 2791 | H25: Klausdalsbrovej 601 | I25: 2750 | J25: 39 | K25: 39 | L25: =SUM(J25:K25) -> 78
B26: 45400 | C26: elbiil.dk - arbejde kontor | D26: 1 | F26: Platanvej 7 | G26: 2791 | H26: Klausdalsbrovej 601 | I26: 2750 | J26: 39 | K26: 39 | L26: =SUM(J26:K26) -> 78
B27: 45406
M75: =(K75-J75)*E75 -> 0
M76: =(K76-J76)*E76 -> 0
C78: (Erhvervsmæssigt) antal kørte kilometer før denne periode i indeværende år
H79: 0 | I79: Dette skal indtastes jf. kørselsregnskab forrige måned i indeværende år
C81: (Erhvervsmæssigt) Antal kørte kilometer i denne måned | H81: =SUM(#REF!) -> #REF! | I81: Beregnes automatisk
C83: Sum antal kørte kilometer erhvervsmæssigt hele året (inkl. denne måned) | H83: =H79+H81 -> #REF! | I83: Beregnes automatisk
C85: Kørte kilometer i denne måned (hvor samlet sum af kørte kilometer i året er under 20.000) | H85: =IF(H83<=20000,H81,IF(H79>20000,0,20000-H79)) -> #REF! | I85: Beregnes automatisk
C87: Kørte kilometer i denne måned (hvor samlet sum af kørte kilometer i året er over 20.000) | H87: =IF(H83>20000,H83-H79-H85,0) -> #REF! | I87: Beregnes automatisk
C89: Fradrag/ godtgørelse pr. km. | D89: 3.79 | E89: (Kørsel til og med 20.000 km. I året, jf. Skattestyrelsens satser for befordringsgodtgørelse i 2021)
D90: 2.23 | E90: (Kørsel udover 20.000 km. I året, jf. Skattestyrelsens sats for befordringsgodtgørelse i 2021)
C92: Kørselsfradrag/kørselsgodtgørelse i perioden: | G92: =(H85*D89)+(H87*D90) -> #REF! | I92: Beregnes automatisk
C94: Godkendt af (underskrift eller stempel)
C96: Dato

Sheet Kørselsgodtgørelse April 2024
B7: Skabelon til kørselsgodtgørelse er fra Dinero Regnskabsprogram
B9: Periode | C9: 45383 | H9: Medarbejderens navn | J9: Sven Arnarsson
B10: Nummerplade | C10: CM73464 | H10: Medarbejderens CPR-nummer | J10: 0411883183
J11: Samlet km | K11: =SUM(L18:L31) -> 640
J12: Sats | K12: 3.79
A13: https://dinero.dk/support/kilometergodtgoerelse/ | J13: Total | K13: =SUM(K11*K12) -> 2425.6
B14: Kørselsregnskab
B16: Dato (skal altid udfyldes) | C16: Beskrivelse (udfyld ved erhverv) | D16: Formålet for kørsel (sæt 1) | F16: Fra (udfyld ved erhverv) | H16: Til (udfyld ved erhverv) | J16: Kilometertæller
D17: Erhverv | E17: Privat | F17: Vejnavn og nr. | G17: Postnummer | H17: Vejnavn og nr. | I17: Postnummer | J17: Frem | K17: Tilbage | L17: Erhverv | M17: Privat
B18: 45383 | C18: elbiil.dk - arbejde kontor | D18: 1 | F18: Platanvej 7 | G18: 2791 | H18: Klausdalsbrovej 601 | I18: 2750 | J18: 39 | K18: 39 | L18: =SUM(J18:K18) -> 78
B19: 45386 | C19: elbiil.dk - arbejde kontor | D19: 1 | F19: Platanvej 7 | G19: 2791 | H19: Klausdalsbrovej 601 | I19: 2750 | J19: 39 | K19: 39 | L19: =SUM(J19:K19) -> 78
B20: 45389 | C20: elbiil.dk - arbejde kontor | D20: 1 | F20: Platanvej 7 | G20: 2791 | H20: Klausdalsbrovej 601 | I20: 2750 | J20: 39 | K20: 39 | L20: =SUM(J20:K20) -> 78
B21: 45392 | C21: elbiil.dk - arbejde kontor | D21: 1 | F21: Platanvej 7 | G21: 2791 | H21: Klausdalsbrovej 601 | I21: 2750 | J21: 39 | K21: 39 | L21: =SUM(J21:K21) -> 78
B22: 45394 | C22: Framehouse første møde | D22: 1 | F22: Platanvej 7 | G22: 2791 | H22: Framehouse, A. P. Møllers Allé 43B, 2791 Dragør | I22: 2791 | J22: 8 | K22: 8 | L22: =SUM(J22:K22) -> 16
B23: 45395 | C23: elbiil.dk - arbejde kontor | D23: 1 | F23: Platanvej 7 | G23: 2791 | H23: Klausdalsbrovej 601 | I23: 2750 | J23: 39 | K23: 39 | L23: =SUM(J23:K23) -> 78
B24: 45398 | C24: elbiil.dk - arbejde kontor | D24: 1 | F24: Platanvej 7 | G24: 2791 | H24: Klausdalsbrovej 601 | I24: 2750 | J24: 39 | K24: 39 | L24: =SUM(J24:K24) -> 78
B25: 45401 | C25: elbiil.dk - arbejde kontor | D25: 1 | F25: Platanvej 7 | G25: 2791 | H25: Klausdalsbrovej 601 | I25: 2750 | J25: 39 | K25: 39 | L25: =SUM(J25:K25) -> 78
B26: 45404 | C26: elbiil.dk - arbejde kontor | D26: 1 | F26: Platanvej 7 | G26: 2791 | H26: Klausdalsbrovej 601 | I26: 2750 | J26: 39 | K26: 39 | L26: =SUM(J26:K26) -> 78
M75: =(K75-J75)*E75 -> 0
M76: =(K76-J76)*E76 -> 0
C78: (Erhvervsmæssigt) antal kørte kilometer før denne periode i indeværende år
H79: 0 | I79: Dette skal indtastes jf. kørselsregnskab forrige måned i indeværende år
C81: (Erhvervsmæssigt) Antal kørte kilometer i denne måned | H81: =SUM(#REF!) -> #REF! | I81: Beregnes automatisk
C83: Sum antal kørte kilometer erhvervsmæssigt hele året (inkl. denne måned) | H83: =H79+H81 -> #REF! | I83: Beregnes automatisk
C85: Kørte kilometer i denne måned (hvor samlet sum af kørte kilometer i året er under 20.000) | H85: =IF(H83<=20000,H81,IF(H79>20000,0,20000-H79)) -> #REF! | I85: Beregnes automatisk
C87: Kørte kilometer i denne måned (hvor samlet sum af kørte kilometer i året er over 20.000) | H87: =IF(H83>20000,H83-H79-H85,0) -> #REF! | I87: Beregnes automatisk
C89: Fradrag/ godtgørelse pr. km. | D89: 3.79 | E89: (Kørsel til og med 20.000 km. I året, jf. Skattestyrelsens satser for befordringsgodtgørelse i 2021)
D90: 2.23 | E90: (Kørsel udover 20.000 km. I året, jf. Skattestyrelsens sats for befordringsgodtgørelse i 2021)
C92: Kørselsfradrag/kørselsgodtgørelse i perioden: | G92: =(H85*D89)+(H87*D90) -> #REF! | I92: Beregnes automatisk
C94: Godkendt af (underskrift eller stempel)
C96: Dato

Sheet Kørselsgodtgørelse Maj 2024
B7: Skabelon til kørselsgodtgørelse er fra Dinero Regnskabsprogram
B9: Periode | C9: 45413 | H9: Medarbejderens navn | J9: Sven Arnarsson
B10: Nummerplade | C10: CM73464 | H10: Medarbejderens CPR-nummer | J10: 0411883183
J11: Samlet km | K11: =SUM(L18:L35) -> 336
J12: Sats | K12: 3.79
A13: https://dinero.dk/support/kilometergodtgoerelse/ | J13: Total | K13: =SUM(K11*K12) -> 1273.44
B14: Kørselsregnskab
B16: Dato (skal altid udfyldes) | C16: Beskrivelse (udfyld ved erhverv) | D16: Formålet for kørsel (sæt 1) | F16: Fra (udfyld ved erhverv) | H16: Til (udfyld ved erhverv) | J16: Kilometertæller
D17: Erhverv | E17: Privat | F17: Vejnavn og nr. | G17: Postnummer | H17: Vejnavn og nr. | I17: Postnummer | J17: Frem | K17: Tilbage | L17: Erhverv | M17: Privat
B18: 45418 | C18: Flexecharge kontor | D18: 1 | F18: Platanvej 7 | G18: 2791 | H18: FLEXeCHARGE, Rahbeks Alle 21 | I18: 1801 | J18: 16 | K18: 16 | L18: =SUM(J18:K18) -> 32
B19: 45419 | C19: Kite Danmark | D19: 1 | F19: Platanvej 7 | G19: 2791 | H19: Kanalholmen 1 1., 2650 Hvidovre, Danmark | I19: 2650 | J19: 20 | K19: 20 | L19: =SUM(J19:K19) -> 40
B20: 45420 | C20: Flexecharge kontor | D20: 1 | F20: Platanvej 7 | G20: 2791 | H20: FLEXeCHARGE, Rahbeks Alle 22 | I20: 1801 | J20: 16 | K20: 16 | L20: =SUM(J20:K20) -> 32
B21: 45425 | C21: Flexecharge kontor | D21: 1 | F21: Platanvej 7 | G21: 2791 | H21: FLEXeCHARGE, Rahbeks Alle 23 | I21: 1801 | J21: 16 | K21: 16 | L21: =SUM(J21:K21) -> 32
B22: 45427 | C22: Flexecharge kontor | D22: 1 | F22: Platanvej 7 | G22: 2791 | H22: FLEXeCHARGE, Rahbeks Alle 24 | I22: 1801 | J22: 16 | K22: 16 | L22: =SUM(J22:K22) -> 32
B23: 45432 | C23: Flexecharge kontor | D23: 1 | F23: Platanvej 7 | G23: 2791 | H23: FLEXeCHARGE, Rahbeks Alle 25 | I23: 1801 | J23: 16 | K23: 16 | L23: =SUM(J23:K23) -> 32
B24: 45434 | C24: Flexecharge kontor | D24: 1 | F24: Platanvej 7 | G24: 2791 | H24: FLEXeCHARGE, Rahbeks Alle 26 | I24: 1801 | J24: 16 | K24: 16 | L24: =SUM(J24:K24) -> 32
B25: 45435 | C25: Kite Danmark | D25: 1 | F25: Platanvej 7 | G25: 2791 | H25: Kanalholmen 1 1., 2650 Hvidovre, Danmark | I25: 2650 | J25: 20 | K25: 20 | L25: =SUM(J25:K25) -> 40
B26: 45439 | C26: Flexecharge kontor | D26: 1 | F26: Platanvej 7 | G26: 2791 | H26: FLEXeCHARGE, Rahbeks Alle 27 | I26: 1801 | J26: 16 | K26: 16 | L26: =SUM(J26:K26) -> 32
B27: 45441 | C27: Flexecharge kontor | D27: 1 | F27: Platanvej 7 | G27: 2791 | H27: FLEXeCHARGE, Rahbeks Alle 28 | I27: 1801 | J27: 16 | K27: 16 | L27: =SUM(J27:K27) -> 32
M79: =(K79-J79)*E79 -> 0
M80: =(K80-J80)*E80 -> 0
C82: (Erhvervsmæssigt) antal kørte kilometer før denne periode i indeværende år
H83: 0 | I83: Dette skal indtastes jf. kørselsregnskab forrige måned i indeværende år
C85: (Erhvervsmæssigt) Antal kørte kilometer i denne måned | H85: =SUM(#REF!) -> #REF! | I85: Beregnes automatisk
C87: Sum antal kørte kilometer erhvervsmæssigt hele året (inkl. denne måned) | H87: =H83+H85 -> #REF! | I87: Beregnes automatisk
C89: Kørte kilometer i denne måned (hvor samlet sum af kørte kilometer i året er under 20.000) | H89: =IF(H87<=20000,H85,IF(H83>20000,0,20000-H83)) -> #REF! | I89: Beregnes automatisk
C91: Kørte kilometer i denne måned (hvor samlet sum af kørte kilometer i året er over 20.000) | H91: =IF(H87>20000,H87-H83-H89,0) -> #REF! | I91: Beregnes automatisk
C93: Fradrag/ godtgørelse pr. km. | D93: 3.79 | E93: (Kørsel til og med 20.000 km. I året, jf. Skattestyrelsens satser for befordringsgodtgørelse i 2021)
D94: 2.23 | E94: (Kørsel udover 20.000 km. I året, jf. Skattestyrelsens sats for befordringsgodtgørelse i 2021)
C96: Kørselsfradrag/kørselsgodtgørelse i perioden: | G96: =(H89*D93)+(H91*D94) -> #REF! | I96: Beregnes automatisk
C98: Godkendt af (underskrift eller stempel)
C100: Dato

Sheet Kørselsgodtgørelse Juni 2024
B7: Skabelon til kørselsgodtgørelse er fra Dinero Regnskabsprogram
B9: Periode | C9: 45444 | H9: Medarbejderens navn | J9: Sven Arnarsson
B10: Nummerplade | C10: CM73464 | H10: Medarbejderens CPR-nummer | J10: 0411883183
J11: Samlet km | K11: =SUM(L18:L32) -> 336 | N11: d
J12: Sats | K12: 3.79
A13: https://dinero.dk/support/kilometergodtgoerelse/ | J13: Total | K13: =SUM(K11*K12) -> 1273.44
B14: Kørselsregnskab
B16: Dato (skal altid udfyldes) | C16: Beskrivelse (udfyld ved erhverv) | D16: Formålet for kørsel (sæt 1) | F16: Fra (udfyld ved erhverv) | H16: Til (udfyld ved erhverv) | J16: Kilometertæller
D17: Erhverv | E17: Privat | F17: Vejnavn og nr. | G17: Postnummer | H17: Vejnavn og nr. | I17: Postnummer | J17: Frem | K17: Tilbage | L17: Erhverv | M17: Privat
B18: 45446 | C18: Flexecharge kontor | D18: 1 | F18: Platanvej 7 | G18: 2791 | H18: FLEXeCHARGE, Rahbeks Alle 21 | I18: 1801 | J18: 16 | K18: 16 | L18: =SUM(J18:K18) -> 32
B19: 45447 | C19: Kite Danmark | D19: 1 | F19: Platanvej 7 | G19: 2791 | H19: Kanalholmen 1 1., 2650 Hvidovre, Danmark | I19: 2650 | J19: 20 | K19: 20 | L19: =SUM(J19:K19) -> 40
B20: 45448 | C20: Flexecharge kontor | D20: 1 | F20: Platanvej 7 | G20: 2791 | H20: FLEXeCHARGE, Rahbeks Alle 22 | I20: 1801 | J20: 16 | K20: 16 | L20: =SUM(J20:K20) -> 32
B21: 45453 | C21: Flexecharge kontor | D21: 1 | F21: Platanvej 7 | G21: 2791 | H21: FLEXeCHARGE, Rahbeks Alle 23 | I21: 1801 | J21: 16 | K21: 16 | L21: =SUM(J21:K21) -> 32
B22: 45454 | C22: Kite Danmark | D22: 1 | F22: Platanvej 7 | G22: 2791 | H22: Kanalholmen 1 1., 2650 Hvidovre, Danmark | I22: 2650 | J22: 20 | K22: 20 | L22: =SUM(J22:K22) -> 40
B23: 45455 | C23: Flexecharge kontor | D23: 1 | F23: Platanvej 7 | G23: 2791 | H23: FLEXeCHARGE, Rahbeks Alle 24 | I23: 1801 | J23: 16 | K23: 16 | L23: =SUM(J23:K23) -> 32
B24: 45460 | C24: Flexecharge kontor | D24: 1 | F24: Platanvej 7 | G24: 2791 | H24: FLEXeCHARGE, Rahbeks Alle 25 | I24: 1801 | J24: 16 | K24: 16 | L24: =SUM(J24:K24) -> 32
B25: 45462 | C25: Flexecharge kontor | D25: 1 | F25: Platanvej 7 | G25: 2791 | H25: FLEXeCHARGE, Rahbeks Alle 26 | I25: 1801 | J25: 16 | K25: 16 | L25: =SUM(J25:K25) -> 32
B26: 45467 | C26: Flexecharge kontor | D26: 1 | F26: Platanvej 7 | G26: 2791 | H26: FLEXeCHARGE, Rahbeks Alle 27 | I26: 1801 | J26: 16 | K26: 16 | L26: =SUM(J26:K26) -> 32
B27: 45469 | C27: Flexecharge kontor | D27: 1 | F27: Platanvej 7 | G27: 2791 | H27: FLEXeCHARGE, Rahbeks Alle 28 | I27: 1801 | J27: 16 | K27: 16 | L27: =SUM(J27:K27) -> 32
M76: =(K76-J76)*E76 -> 0
M77: =(K77-J77)*E77 -> 0
C79: (Erhvervsmæssigt) antal kørte kilometer før denne periode i indeværende år
H80: 0 | I80: Dette skal indtastes jf. kørselsregnskab forrige måned i indeværende år
C82: (Erhvervsmæssigt) Antal kørte kilometer i denne måned | H82: =SUM(#REF!) -> #REF! | I82: Beregnes automatisk
C84: Sum antal kørte kilometer erhvervsmæssigt hele året (inkl. denne måned) | H84: =H80+H82 -> #REF! | I84: Beregnes automatisk
C86: Kørte kilometer i denne måned (hvor samlet sum af kørte kilometer i året er under 20.000) | H86: =IF(H84<=20000,H82,IF(H80>20000,0,20000-H80)) -> #REF! | I86: Beregnes automatisk
C88: Kørte kilometer i denne måned (hvor samlet sum af kørte kilometer i året er over 20.000) | H88: =IF(H84>20000,H84-H80-H86,0) -> #REF! | I88: Beregnes automatisk
C90: Fradrag/ godtgørelse pr. km. | D90: 3.79 | E90: (Kørsel til og med 20.000 km. I året, jf. Skattestyrelsens satser for befordringsgodtgørelse i 2021)
D91: 2.23 | E91: (Kørsel udover 20.000 km. I året, jf. Skattestyrelsens sats for befordringsgodtgørelse i 2021)
C93: Kørselsfradrag/kørselsgodtgørelse i perioden: | G93: =(H86*D90)+(H88*D91) -> #REF! | I93: Beregnes automatisk
C95: Godkendt af (underskrift eller stempel)
C97: Dato

Sheet Kørselsgodtgørelse Juli 2024
B7: Skabelon til kørselsgodtgørelse er fra Dinero Regnskabsprogram
B9: Periode | C9: 45474 | H9: Medarbejderens navn | J9: Sven Arnarsson
B10: Nummerplade | C10: CM73464 | H10: Medarbejderens CPR-nummer | J10: 0411883183
J11: Samlet km | K11: =SUM(L18:L30) -> 258 | N11: d
J12: Sats | K12: 3.79
A13: https://dinero.dk/support/kilometergodtgoerelse/ | J13: Total | K13: =SUM(K11*K12) -> 977.82
B14: Kørselsregnskab
B16: Dato (skal altid udfyldes) | C16: Beskrivelse (udfyld ved erhverv) | D16: Formålet for kørsel (sæt 1) | F16: Fra (udfyld ved erhverv) | H16: Til (udfyld ved erhverv) | J16: Kilometertæller
D17: Erhverv | E17: Privat | F17: Vejnavn og nr. | G17: Postnummer | H17: Vejnavn og nr. | I17: Postnummer | J17: Frem | K17: Tilbage | L17: Erhverv | M17: Privat
B18: 45474 | C18: WARM kontor | D18: 1 | F18: Platanvej 7 | G18: 2791 | H18: Birkedommervej 31 | I18: 2400 | J18: 23 | K18: 23 | L18: =SUM(J18:K18) -> 46
B19: 45474 | C19: Flexecharge kontor | D19: 1 | F19: Platanvej 7 | G19: 2791 | H19: FLEXeCHARGE, Rahbeks Alle 21 | I19: 1801 | J19: 16 | K19: 16 | L19: =SUM(J19:K19) -> 32
B20: 45447 | C20: Kite Danmark | D20: 1 | F20: Platanvej 7 | G20: 2791 | H20: Kanalholmen 1 1., 2650 Hvidovre, Danmark | I20: 2650 | J20: 20 | K20: 20 | L20: =SUM(J20:K20) -> 40
B21: 45481 | C21: Flexecharge kontor | D21: 1 | F21: Platanvej 7 | G21: 2791 | H21: FLEXeCHARGE, Rahbeks Alle 21 | I21: 1801 | J21: 16 | K21: 16 | L21: =SUM(J21:K21) -> 32
B22: 45454 | C22: Kite Danmark | D22: 1 | F22: Platanvej 7 | G22: 2791 | H22: Kanalholmen 1 1., 2650 Hvidovre, Danmark | I22: 2650 | J22: 20 | K22: 20 | L22: =SUM(J22:K22) -> 40
B23: 45488 | C23: Flexecharge kontor | D23: 1 | F23: Platanvej 7 | G23: 2791 | H23: FLEXeCHARGE, Rahbeks Alle 21 | I23: 1801 | J23: 16 | K23: 16 | L23: =SUM(J23:K23) -> 32
B24: 45492 | C24: møde med Bigum | D24: 1 | F24: Platanvej 7 | G24: 2791 | H24: Bigum&Co, Rued Langgaards Vej | I24: 2300 | J24: 18 | K24: 18 | L24: =SUM(J24:K24) -> 36
M74: =(K74-J74)*E74 -> 0
M75: =(K75-J75)*E75 -> 0
C77: (Erhvervsmæssigt) antal kørte kilometer før denne periode i indeværende år
H78: 0 | I78: Dette skal indtastes jf. kørselsregnskab forrige måned i indeværende år
C80: (Erhvervsmæssigt) Antal kørte kilometer i denne måned | H80: =SUM(#REF!) -> #REF! | I80: Beregnes automatisk
C82: Sum antal kørte kilometer erhvervsmæssigt hele året (inkl. denne måned) | H82: =H78+H80 -> #REF! | I82: Beregnes automatisk
C84: Kørte kilometer i denne måned (hvor samlet sum af kørte kilometer i året er under 20.000) | H84: =IF(H82<=20000,H80,IF(H78>20000,0,20000-H78)) -> #REF! | I84: Beregnes automatisk
C86: Kørte kilometer i denne måned (hvor samlet sum af kørte kilometer i året er over 20.000) | H86: =IF(H82>20000,H82-H78-H84,0) -> #REF! | I86: Beregnes automatisk
C88: Fradrag/ godtgørelse pr. km. | D88: 3.79 | E88: (Kørsel til og med 20.000 km. I året, jf. Skattestyrelsens satser for befordringsgodtgørelse i 2021)
D89: 2.23 | E89: (Kørsel udover 20.000 km. I året, jf. Skattestyrelsens sats for befordringsgodtgørelse i 2021)
C91: Kørselsfradrag/kørselsgodtgørelse i perioden: | G91: =(H84*D88)+(H86*D89) -> #REF! | I91: Beregnes automatisk
C93: Godkendt af (underskrift eller stempel)
C95: Dato

Sheet Kørselsgodtgørelse Aug 2024
B7: Skabelon til kørselsgodtgørelse er fra Dinero Regnskabsprogram
B9: Periode | C9: 45505 | H9: Medarbejderens navn | J9: Sven Arnarsson
B10: Nummerplade | C10: CM73464 | H10: Medarbejderens CPR-nummer | J10: 0411883183
J11: Samlet km | K11: =SUM(L18:L29) -> 807 | N11: d
J12: Sats | K12: 3.79
A13: https://dinero.dk/support/kilometergodtgoerelse/ | J13: Total | K13: =SUM(K11*K12) -> 3058.53
B14: Kørselsregnskab
B16: Dato (skal altid udfyldes) | C16: Beskrivelse (udfyld ved erhverv) | D16: Formålet for kørsel (sæt 1) | F16: Fra (udfyld ved erhverv) | H16: Til (udfyld ved erhverv) | J16: Kilometertæller
D17: Erhverv | E17: Privat | F17: Vejnavn og nr. | G17: Postnummer | H17: Vejnavn og nr. | I17: Postnummer | J17: Frem | K17: Tilbage | L17: Erhverv | M17: Privat
B18: 45505 | C18: Forretning i vejen | D18: 1 | F18: Platanvej 7 | G18: 2791 | H18: Vejen Rådhusplads Cafe | I18: 6600 | J18: 257 | K18: 257 | L18: =SUM(J18:K18) -> 514
B19: 45511 | C19: Bigum og Co | D19: 1 | F19: Platanvej 7 | G19: 2791 | H19: Bigum&Co, Rued Langgaards Vej 8, 2300 København | I19: 2300 | J19: 14 | K19: 14 | L19: =SUM(J19:K19) -> 28
B20: 45511 | C20: Møde med Seven Oceans | D20: 1 | F20: Platanvej 7 | G20: 2791 | H20: Bryghusgade 8, 1473 | I20: 2300 | J20: 18 | K20: 18 | L20: =SUM(J20:K20) -> 36
B21: 45523 | C21: Bigum og Co | D21: 1 | F21: Platanvej 7 | G21: 2791 | H21: Bigum&Co, Rued Langgaards Vej 8, 2300 København | I21: 2300 | J21: 18 | K21: 18 | L21: =SUM(J21:K21) -> 36
B22: 45526 | C22: Bigum og Co | D22: 1 | F22: Platanvej 7 | G22: 2791 | H22: Bigum&Co, Rued Langgaards Vej 8, 2300 København | I22: 2300 | J22: 18 | K22: 18 | L22: =SUM(J22:K22) -> 36
B23: 45533 | C23: Bigum og Co | D23: 1 | F23: Platanvej 7 | G23: 2791 | H23: Bigum&Co, Rued Langgaards Vej 8, 2300 København | I23: 2300 | J23: 18 | K23: 18 | L23: =SUM(J23:K23) -> 36
B24: 45531 | C24: Bigum og Co | D24: 1 | F24: Platanvej 7 | G24: 2791 | H24: Bigum&Co, Rued Langgaards Vej 8, 2300 København | I24: 2300 | J24: 18 | K24: 18 | L24: =SUM(J24:K24) -> 36
B25: 45533 | C25: Werner Valeur Intro | D25: 1 | F25: Platanvej 7 | G25: 2791 | H25: Werner Valeur | I25: 2840 | J25: 42.5 | K25: 42.5 | L25: =SUM(J25:K25) -> 85
M73: =(K73-J73)*E73 -> 0
M74: =(K74-J74)*E74 -> 0
C76: (Erhvervsmæssigt) antal kørte kilometer før denne periode i indeværende år
H77: 0 | I77: Dette skal indtastes jf. kørselsregnskab forrige måned i indeværende år
C79: (Erhvervsmæssigt) Antal kørte kilometer i denne måned | H79: =SUM(#REF!) -> #REF! | I79: Beregnes automatisk
C81: Sum antal kørte kilometer erhvervsmæssigt hele året (inkl. denne måned) | H81: =H77+H79 -> #REF! | I81: Beregnes automatisk
C83: Kørte kilometer i denne måned (hvor samlet sum af kørte kilometer i året er under 20.000) | H83: =IF(H81<=20000,H79,IF(H77>20000,0,20000-H77)) -> #REF! | I83: Beregnes automatisk
C85: Kørte kilometer i denne måned (hvor samlet sum af kørte kilometer i året er over 20.000) | H85: =IF(H81>20000,H81-H77-H83,0) -> #REF! | I85: Beregnes automatisk
C87: Fradrag/ godtgørelse pr. km. | D87: 3.79 | E87: (Kørsel til og med 20.000 km. I året, jf. Skattestyrelsens satser for befordringsgodtgørelse i 2021)
D88: 2.23 | E88: (Kørsel udover 20.000 km. I året, jf. Skattestyrelsens sats for befordringsgodtgørelse i 2021)
C90: Kørselsfradrag/kørselsgodtgørelse i perioden: | G90: =(H83*D87)+(H85*D88) -> #REF! | I90: Beregnes automatisk
C92: Godkendt af (underskrift eller stempel)
C94: Dato

Sheet Kørselsgodtgørelse Sept 2024
B7: Skabelon til kørselsgodtgørelse er fra Dinero Regnskabsprogram
B9: Periode | C9: 45536 | H9: Medarbejderens navn | J9: Sven Arnarsson
B10: Nummerplade | C10: CM73464 | H10: Medarbejderens CPR-nummer | J10: 0411883183
J11: Samlet km | K11: =SUM(L18:L31) -> 348 | N11: d
J12: Sats | K12: 3.79
A13: https://dinero.dk/support/kilometergodtgoerelse/ | J13: Total | K13: =SUM(K11*K12) -> 1318.92
B14: Kørselsregnskab
B16: Dato (skal altid udfyldes) | C16: Beskrivelse (udfyld ved erhverv) | D16: Formålet for kørsel (sæt 1) | F16: Fra (udfyld ved erhverv) | H16: Til (udfyld ved erhverv) | J16: Kilometertæller
D17: Erhverv | E17: Privat | F17: Vejnavn og nr. | G17: Postnummer | H17: Vejnavn og nr. | I17: Postnummer | J17: Frem | K17: Tilbage | L17: Erhverv | M17: Privat
B18: 45539 | C18: Bigum og Co | D18: 1 | F18: Platanvej 7 | G18: 2791 | H18: Bigum&Co, Rued Langgaards Vej 8, 2300 København | I18: 2300 | J18: 14 | K18: 14 | L18: =SUM(J18:K18) -> 28
B19: 45540 | C19: Flexecharge møde | F19: Platanvej 7 | G19: 2791 | H19: FLEXeCHARGE, Rahbeks Alle 21 | I19: 1801 | J19: 16 | K19: 16 | L19: =SUM(J19:K19) -> 32
B20: 45541 | C20: Bigum og Co | D20: 1 | F20: Platanvej 7 | G20: 2791 | H20: Bigum&Co, Rued Langgaards Vej 8, 2300 København | I20: 2300 | J20: 14 | K20: 14 | L20: =SUM(J20:K20) -> 28
B21: 45544 | C21: Bigum og Co | D21: 1 | F21: Platanvej 7 | G21: 2791 | H21: Bigum&Co, Rued Langgaards Vej 8, 2300 København | I21: 2300 | J21: 14 | K21: 14 | L21: =SUM(J21:K21) -> 28
B22: 45551 | C22: Bigum og Co | D22: 1 | F22: Platanvej 7 | G22: 2791 | H22: Bigum&Co, Rued Langgaards Vej 8, 2300 København | I22: 2300 | J22: 14 | K22: 14 | L22: =SUM(J22:K22) -> 28
B23: 45553 | C23: Bigum og Co | D23: 1 | F23: Platanvej 7 | G23: 2791 | H23: Bigum&Co, Rued Langgaards Vej 8, 2300 København | I23: 2300 | J23: 14 | K23: 14 | L23: =SUM(J23:K23) -> 28
B24: 45555 | C24: Bigum og Co | D24: 1 | F24: Platanvej 7 | G24: 2791 | H24: Bigum&Co, Rued Langgaards Vej 8, 2300 København | I24: 2300 | J24: 14 | K24: 14 | L24: =SUM(J24:K24) -> 28
B25: 45558 | C25: Bigum og Co | D25: 1 | F25: Platanvej 7 | G25: 2791 | H25: Bigum&Co, Rued Langgaards Vej 8, 2300 København | I25: 2300 | J25: 14 | K25: 14 | L25: =SUM(J25:K25) -> 28
B26: 45559 | C26: Flexecharge møde | D26: 1 | F26: Platanvej 7 | G26: 2791 | H26: FLEXeCHARGE, Rahbeks Alle 21 | I26: 1801 | J26: 16 | K26: 16 | L26: =SUM(J26:K26) -> 32
B27: 45560 | C27: Bigum og Co | D27: 1 | F27: Platanvej 7 | G27: 2791 | H27: Bigum&Co, Rued Langgaards Vej 8, 2300 København | I27: 2300 | J27: 14 | K27: 14 | L27: =SUM(J27:K27) -> 28
B28: 45561 | C28: Flexecharge møde | D28: 1 | F28: Platanvej 7 | G28: 2791 | H28: FLEXeCHARGE, Rahbeks Alle 21 | I28: 1801 | J28: 16 | K28: 16 | L28: =SUM(J28:K28) -> 32
B29: 45562 | C29: Bigum og Co | D29: 1 | F29: Platanvej 7 | G29: 2791 | H29: Bigum&Co, Rued Langgaards Vej 8, 2300 København | I29: 2300 | J29: 14 | K29: 14 | L29: =SUM(J29:K29) -> 28
M75: =(K75-J75)*E75 -> 0
M76: =(K76-J76)*E76 -> 0
C78: (Erhvervsmæssigt) antal kørte kilometer før denne periode i indeværende år
H79: 0 | I79: Dette skal indtastes jf. kørselsregnskab forrige måned i indeværende år
C81: (Erhvervsmæssigt) Antal kørte kilometer i denne måned | H81: =SUM(#REF!) -> #REF! | I81: Beregnes automatisk
C83: Sum antal kørte kilometer erhvervsmæssigt hele året (inkl. denne måned) | H83: =H79+H81 -> #REF! | I83: Beregnes automatisk
C85: Kørte kilometer i denne måned (hvor samlet sum af kørte kilometer i året er under 20.000) | H85: =IF(H83<=20000,H81,IF(H79>20000,0,20000-H79)) -> #REF! | I85: Beregnes automatisk
C87: Kørte kilometer i denne måned (hvor samlet sum af kørte kilometer i året er over 20.000) | H87: =IF(H83>20000,H83-H79-H85,0) -> #REF! | I87: Beregnes automatisk
C89: Fradrag/ godtgørelse pr. km. | D89: 3.79 | E89: (Kørsel til og med 20.000 km. I året, jf. Skattestyrelsens satser for befordringsgodtgørelse i 2021)
D90: 2.23 | E90: (Kørsel udover 20.000 km. I året, jf. Skattestyrelsens sats for befordringsgodtgørelse i 2021)
C92: Kørselsfradrag/kørselsgodtgørelse i perioden: | G92: =(H85*D89)+(H87*D90) -> #REF! | I92: Beregnes automatisk
C94: Godkendt af (underskrift eller stempel)
C96: Dato

Sheet Kørselsgodtgørelse Okt 2024
B7: Skabelon til kørselsgodtgørelse er fra Dinero Regnskabsprogram
B9: Periode | C9: 45566 | H9: Medarbejderens navn | J9: Sven Arnarsson
B10: Nummerplade | C10: CM73464 | H10: Medarbejderens CPR-nummer | J10: 0411883183
J11: Samlet km | K11: =SUM(L18:L28) -> 672 | N11: d
J12: Sats | K12: 3.79
A13: https://dinero.dk/support/kilometergodtgoerelse/ | J13: Total | K13: =SUM(K11*K12) -> 2546.88
B14: Kørselsregnskab
B16: Dato (skal altid udfyldes) | C16: Beskrivelse (udfyld ved erhverv) | D16: Formålet for kørsel (sæt 1) | F16: Fra (udfyld ved erhverv) | H16: Til (udfyld ved erhverv) | J16: Kilometertæller
D17: Erhverv | E17: Privat | F17: Vejnavn og nr. | G17: Postnummer | H17: Vejnavn og nr. | I17: Postnummer | J17: Frem | K17: Tilbage | L17: Erhverv | M17: Privat
B18: 45568 | C18: Bigum og Co | D18: 1 | F18: Platanvej 7 | G18: 2791 | H18: Smedeholm 12, 2730 Herlev | I18: 2730 | J18: 40 | K18: 40 | L18: =SUM(J18:K18) -> 80
B19: 45572 | C19: Bigum og Co | D19: 1 | F19: Platanvej 7 | G19: 2791 | H19: Smedeholm 12, 2730 Herlev | I19: 2730 | J19: 40 | K19: 40 | L19: =SUM(J19:K19) -> 80
B20: 45573 | C20: Flexecharge møde | D20: 1 | F20: Platanvej 7 | G20: 2791 | H20: FLEXeCHARGE, Rahbeks Alle 21 | I20: 1801 | J20: 16 | K20: 16 | L20: =SUM(J20:K20) -> 32
B21: 45576 | C21: Bigum og Co | D21: 1 | F21: Platanvej 7 | G21: 2791 | H21: Smedeholm 12, 2730 Herlev | I21: 2730 | J21: 40 | K21: 40 | L21: =SUM(J21:K21) -> 80
B22: 45579 | C22: Bigum og Co | D22: 1 | F22: Platanvej 7 | G22: 2791 | H22: Smedeholm 12, 2730 Herlev | I22: 2730 | J22: 40 | K22: 40 | L22: =SUM(J22:K22) -> 80
B23: 45588 | C23: Bigum og Co | D23: 1 | F23: Platanvej 7 | G23: 2791 | H23: Smedeholm 12, 2730 Herlev | I23: 2730 | J23: 40 | K23: 40 | L23: =SUM(J23:K23) -> 80
B24: 45589 | C24: Bigum og Co | D24: 1 | F24: Platanvej 7 | G24: 2791 | H24: Smedeholm 12, 2730 Herlev | I24: 2730 | J24: 40 | K24: 40 | L24: =SUM(J24:K24) -> 80
B25: 45590 | C25: Bigum og Co | D25: 1 | F25: Platanvej 7 | G25: 2791 | H25: Smedeholm 12, 2730 Herlev | I25: 2730 | J25: 40 | K25: 40 | L25: =SUM(J25:K25) -> 80
B26: 45594 | C26: Bigum og Co | D26: 1 | F26: Platanvej 7 | G26: 2791 | H26: Smedeholm 12, 2730 Herlev | I26: 2730 | J26: 40 | K26: 40 | L26: =SUM(J26:K26) -> 80
M72: =(K72-J72)*E72 -> 0
M73: =(K73-J73)*E73 -> 0
C75: (Erhvervsmæssigt) antal kørte kilometer før denne periode i indeværende år
H76: 0 | I76: Dette skal indtastes jf. kørselsregnskab forrige måned i indeværende år
C78: (Erhvervsmæssigt) Antal kørte kilometer i denne måned | H78: =SUM(#REF!) -> #REF! | I78: Beregnes automatisk
C80: Sum antal kørte kilometer erhvervsmæssigt hele året (inkl. denne måned) | H80: =H76+H78 -> #REF! | I80: Beregnes automatisk
C82: Kørte kilometer i denne måned (hvor samlet sum af kørte kilometer i året er under 20.000) | H82: =IF(H80<=20000,H78,IF(H76>20000,0,20000-H76)) -> #REF! | I82: Beregnes automatisk
C84: Kørte kilometer i denne måned (hvor samlet sum af kørte kilometer i året er over 20.000) | H84: =IF(H80>20000,H80-H76-H82,0) -> #REF! | I84: Beregnes automatisk
C86: Fradrag/ godtgørelse pr. km. | D86: 3.79 | E86: (Kørsel til og med 20.000 km. I året, jf. Skattestyrelsens satser for befordringsgodtgørelse i 2021)
D87: 2.23 | E87: (Kørsel udover 20.000 km. I året, jf. Skattestyrelsens sats for befordringsgodtgørelse i 2021)
C89: Kørselsfradrag/kørselsgodtgørelse i perioden: | G89: =(H82*D86)+(H84*D87) -> #REF! | I89: Beregnes automatisk
C91: Godkendt af (underskrift eller stempel)
C93: Dato

Sheet Kørselsgodtgørelse Nov 2024
B7: Skabelon til kørselsgodtgørelse er fra Dinero Regnskabsprogram
B9: Periode | C9: 45604 | H9: Medarbejderens navn | J9: Sven Arnarsson
B10: Nummerplade | C10: CM73464 | H10: Medarbejderens CPR-nummer | J10: 0411883183
J11: Samlet km | K11: =SUM(L18:L30) -> 512 | N11: d
J12: Sats | K12: 3.79
A13: https://dinero.dk/support/kilometergodtgoerelse/ | J13: Total | K13: =SUM(K11*K12) -> 1940.48
B14: Kørselsregnskab
B16: Dato (skal altid udfyldes) | C16: Beskrivelse (udfyld ved erhverv) | D16: Formålet for kørsel (sæt 1) | F16: Fra (udfyld ved erhverv) | H16: Til (udfyld ved erhverv) | J16: Kilometertæller
D17: Erhverv | E17: Privat | F17: Vejnavn og nr. | G17: Postnummer | H17: Vejnavn og nr. | I17: Postnummer | J17: Frem | K17: Tilbage | L17: Erhverv | M17: Privat
B18: 45601 | C18: Flexecharge kontor | D18: 1 | F18: Platanvej 7 | G18: 2791 | H18: FLEXeCHARGE, Rahbeks Alle 21 | I18: 1801 | J18: 16 | K18: 16 | L18: =SUM(J18:K18) -> 32
B19: 45600 | C19: Bigum og Co | D19: 1 | F19: Platanvej 7 | G19: 2791 | H19: Smedeholm 12, 2730 Herlev | I19: 2730 | J19: 40 | K19: 40 | L19: =SUM(J19:K19) -> 80
B20: 45602 | C20: Bigum og Co | D20: 1 | F20: Platanvej 7 | G20: 2791 | H20: Smedeholm 12, 2730 Herlev | I20: 2730 | J20: 40 | K20: 40 | L20: =SUM(J20:K20) -> 80
B21: 45608 | C21: Bigum og Co | D21: 1 | F21: Platanvej 7 | G21: 2791 | H21: Smedeholm 12, 2730 Herlev | I21: 2730 | J21: 40 | K21: 40 | L21: =SUM(J21:K21) -> 80
B22: 45609 | C22: Bigum og Co | D22: 1 | F22: Platanvej 7 | G22: 2791 | H22: Smedeholm 12, 2730 Herlev | I22: 2730 | J22: 40 | K22: 40 | L22: =SUM(J22:K22) -> 80
B23: 45610 | C23: Bigum og Co | D23: 1 | F23: Platanvej 7 | G23: 2791 | H23: Smedeholm 12, 2730 Herlev | I23: 2730 | J23: 40 | K23: 40 | L23: =SUM(J23:K23) -> 80
B24: 45611 | C24: Bigum og Co | D24: 1 | F24: Platanvej 7 | G24: 2791 | H24: Smedeholm 12, 2730 Herlev | I24: 2730 | J24: 40 | K24: 40 | L24: =SUM(J24:K24) -> 80
M74: =(K74-J74)*E74 -> 0
M75: =(K75-J75)*E75 -> 0
C77: (Erhvervsmæssigt) antal kørte kilometer før denne periode i indeværende år
H78: 0 | I78: Dette skal indtastes jf. kørselsregnskab forrige måned i indeværende år
C80: (Erhvervsmæssigt) Antal kørte kilometer i denne måned | H80: =SUM(#REF!) -> #REF! | I80: Beregnes automatisk
C82: Sum antal kørte kilometer erhvervsmæssigt hele året (inkl. denne måned) | H82: =H78+H80 -> #REF! | I82: Beregnes automatisk
C84: Kørte kilometer i denne måned (hvor samlet sum af kørte kilometer i året er under 20.000) | H84: =IF(H82<=20000,H80,IF(H78>20000,0,20000-H78)) -> #REF! | I84: Beregnes automatisk
C86: Kørte kilometer i denne måned (hvor samlet sum af kørte kilometer i året er over 20.000) | H86: =IF(H82>20000,H82-H78-H84,0) -> #REF! | I86: Beregnes automatisk
C88: Fradrag/ godtgørelse pr. km. | D88: 3.79 | E88: (Kørsel til og med 20.000 km. I året, jf. Skattestyrelsens satser for befordringsgodtgørelse i 2021)
D89: 2.23 | E89: (Kørsel udover 20.000 km. I året, jf. Skattestyrelsens sats for befordringsgodtgørelse i 2021)
C91: Kørselsfradrag/kørselsgodtgørelse i perioden: | G91: =(H84*D88)+(H86*D89) -> #REF! | I91: Beregnes automatisk
C93: Godkendt af (underskrift eller stempel)
C95: Dato

Sheet Kørselsgodtgørelse Dec 2024
B7: Skabelon til kørselsgodtgørelse er fra Dinero Regnskabsprogram
B9: Periode | C9: 45636 | H9: Medarbejderens navn | J9: Sven Arnarsson
B10: Nummerplade | C10: CM73464 | H10: Medarbejderens CPR-nummer | J10: 0411883183
J11: Samlet km | K11: =SUM(L18:L30) -> 1040 | N11: d
J12: Sats | K12: 3.79
A13: https://dinero.dk/support/kilometergodtgoerelse/ | J13: Total | K13: =SUM(K11*K12) -> 3941.6
B14: Kørselsregnskab
B16: Dato (skal altid udfyldes) | C16: Beskrivelse (udfyld ved erhverv) | D16: Formålet for kørsel (sæt 1) | F16: Fra (udfyld ved erhverv) | H16: Til (udfyld ved erhverv) | J16: Kilometertæller
D17: Erhverv | E17: Privat | F17: Vejnavn og nr. | G17: Postnummer | H17: Vejnavn og nr. | I17: Postnummer | J17: Frem | K17: Tilbage | L17: Erhverv | M17: Privat
B18: 45628 | C18: Bigum og Co | D18: 1 | F18: Platanvej 7 | G18: 2791 | H18: Smedeholm 12, 2730 Herlev | I18: 2730 | J18: 40 | K18: 40 | L18: =SUM(J18:K18) -> 80
B19: 45629 | C19: Bigum og Co | D19: 1 | F19: Platanvej 7 | G19: 2791 | H19: Smedeholm 12, 2730 Herlev | I19: 2730 | J19: 40 | K19: 40 | L19: =SUM(J19:K19) -> 80
B20: 45632 | C20: Bigum og Co | D20: 1 | F20: Platanvej 7 | G20: 2791 | H20: Smedeholm 12, 2730 Herlev | I20: 2730 | J20: 40 | K20: 40 | L20: =SUM(J20:K20) -> 80
B21: 45635 | C21: Bigum og Co | D21: 1 | F21: Platanvej 7 | G21: 2791 | H21: Smedeholm 12, 2730 Herlev | I21: 2730 | J21: 40 | K21: 40 | L21: =SUM(J21:K21) -> 80
B22: 45637 | C22: Bigum og Co | D22: 1 | F22: Platanvej 7 | G22: 2791 | H22: Smedeholm 12, 2730 Herlev | I22: 2730 | J22: 40 | K22: 40 | L22: =SUM(J22:K22) -> 80
B23: 45638 | C23: Bigum og Co | D23: 1 | F23: Platanvej 7 | G23: 2791 | H23: Smedeholm 12, 2730 Herlev | I23: 2730 | J23: 40 | K23: 40 | L23: =SUM(J23:K23) -> 80
B24: 45639 | C24: Bigum og Co | D24: 1 | F24: Platanvej 7 | G24: 2791 | H24: Smedeholm 12, 2730 Herlev | I24: 2730 | J24: 40 | K24: 40 | L24: =SUM(J24:K24) -> 80
B25: 45640 | C25: Potentiel kunde i Kolding | D25: 1 | F25: Platanvej 7 | G25: 2791 | H25: Lilletorv 16, Danmark | I25: 6000 | J25: 240 | K25: 240 | L25: =SUM(J25:K25) -> 480
M74: =(K74-J74)*E74 -> 0
M75: =(K75-J75)*E75 -> 0
C77: (Erhvervsmæssigt) antal kørte kilometer før denne periode i indeværende år
H78: 0 | I78: Dette skal indtastes jf. kørselsregnskab forrige måned i indeværende år
C80: (Erhvervsmæssigt) Antal kørte kilometer i denne måned | H80: =SUM(#REF!) -> #REF! | I80: Beregnes automatisk
C82: Sum antal kørte kilometer erhvervsmæssigt hele året (inkl. denne måned) | H82: =H78+H80 -> #REF! | I82: Beregnes automatisk
C84: Kørte kilometer i denne måned (hvor samlet sum af kørte kilometer i året er under 20.000) | H84: =IF(H82<=20000,H80,IF(H78>20000,0,20000-H78)) -> #REF! | I84: Beregnes automatisk
C86: Kørte kilometer i denne måned (hvor samlet sum af kørte kilometer i året er over 20.000) | H86: =IF(H82>20000,H82-H78-H84,0) -> #REF! | I86: Beregnes automatisk
C88: Fradrag/ godtgørelse pr. km. | D88: 3.79 | E88: (Kørsel til og med 20.000 km. I året, jf. Skattestyrelsens satser for befordringsgodtgørelse i 2021)
D89: 2.23 | E89: (Kørsel udover 20.000 km. I året, jf. Skattestyrelsens sats for befordringsgodtgørelse i 2021)
C91: Kørselsfradrag/kørselsgodtgørelse i perioden: | G91: =(H84*D88)+(H86*D89) -> #REF! | I91: Beregnes automatisk
C93: Godkendt af (underskrift eller stempel)
C95: Dato

Sheet Kørselsgodtgørelse Jan 2025
B7: Skabelon til kørselsgodtgørelse er fra Dinero Regnskabsprogram
B9: Periode | C9: 45658 | H9: Medarbejderens navn | J9: Sven Arnarsson
B10: Nummerplade | C10: CM73464 | H10: Medarbejderens CPR-nummer | J10: 0411883183
J11: Samlet km | K11: =SUM(L18:L35) -> 748 | N11: d
J12: Sats | K12: 3.81
A13: https://dinero.dk/support/kilometergodtgoerelse/ | J13: Total | K13: =SUM(K11*K12) -> 2849.88
B14: Kørselsregnskab
B16: Dato (skal altid udfyldes) | C16: Beskrivelse (udfyld ved erhverv) | D16: Formålet for kørsel (sæt 1) | F16: Fra (udfyld ved erhverv) | H16: Til (udfyld ved erhverv) | J16: Kilometertæller
D17: Erhverv | E17: Privat | F17: Vejnavn og nr. | G17: Postnummer | H17: Vejnavn og nr. | I17: Postnummer | J17: Frem | K17: Tilbage | L17: Erhverv | M17: Privat
B18: 45665 | C18: Talent garden | D18: 1 | F18: Platanvej 7 | G18: 2791 | H18: Danneskiold-Samsøes Allé 41 | I18: 1434 | J18: 19 | K18: 19 | L18: =SUM(J18:K18) -> 38
B19: 45666 | C19: Talent garden | D19: 1 | F19: Platanvej 7 | G19: 2791 | H19: Danneskiold-Samsøes Allé 41 | I19: 1434 | J19: 19 | K19: 19 | L19: =SUM(J19:K19) -> 38
B20: 45664 | C20: Founders Dinner | D20: 1 | F20: Platanvej 7 | G20: 2791 | H20: Admiralgade 25 | I20: 1066 | J20: 17 | K20: 17 | L20: =SUM(J20:K20) -> 34
B21: 45670 | C21: Bigum og Co | D21: 1 | F21: Platanvej 7 | G21: 2791 | H21: Smedeholm 12, 2730 Herlev | I21: 2730 | J21: 40 | K21: 40 | L21: =SUM(J21:K21) -> 80
B22: 45674 | C22: Bigum og Co | D22: 1 | F22: Platanvej 7 | G22: 2791 | H22: Smedeholm 12, 2730 Herlev | I22: 2730 | J22: 40 | K22: 40 | L22: =SUM(J22:K22) -> 80
B23: 45672 | C23: Talent garden | D23: 1 | F23: Platanvej 7 | G23: 2791 | H23: Danneskiold-Samsøes Allé 41 | I23: 1434 | J23: 19 | K23: 19 | L23: =SUM(J23:K23) -> 38
B24: 45673 | C24: Talent garden | D24: 1 | F24: Platanvej 7 | G24: 2791 | H24: Danneskiold-Samsøes Allé 41 | I24: 1434 | J24: 19 | K24: 19 | L24: =SUM(J24:K24) -> 38
B25: 45677 | C25: Bigum og Co | D25: 1 | F25: Platanvej 7 | G25: 2791 | H25: Smedeholm 12, 2730 Herlev | I25: 2730 | J25: 40 | K25: 40 | L25: =SUM(J25:K25) -> 80
B26: 45678 | C26: Bigum og Co | D26: 1 | F26: Platanvej 7 | G26: 2791 | H26: Smedeholm 12, 2730 Herlev | I26: 2730 | J26: 40 | K26: 40 | L26: =SUM(J26:K26) -> 80
B27: 45679 | C27: Bigum og Co | D27: 1 | F27: Platanvej 7 | G27: 2791 | H27: Smedeholm 12, 2730 Herlev | I27: 2730 | J27: 40 | K27: 40 | L27: =SUM(J27:K27) -> 80
B28: 45679 | C28: Nytårskur Dragør kommune | D28: 1 | F28: Platanvej 7 | G28: 2791 | H28: Kirkevej 7, 2791 Dragør, Danmark | I28: 2730 | J28: 5 | K28: 5 | L28: =SUM(J28:K28) -> 10
B29: 45680 | C29: Talent garden | D29: 1 | F29: Platanvej 7 | G29: 2791 | H29: Danneskiold-Samsøes Allé 41 | I29: 1434 | J29: 19 | K29: 19 | L29: =SUM(J29:K29) -> 38
... B32: 45687 | C32: Talent garden | D32: 1 | F32: Platanvej 7 | G32: 2791 | H32: Danneskiold-Samsøes Allé 41 | I32: 1434 | J32: 19 | K32: 19 | L32: =SUM(J32:K32) -> 38
M79: =(K79-J79)*E79 -> 0
M80: =(K80-J80)*E80 -> 0
C82: (Erhvervsmæssigt) antal kørte kilometer før denne periode i indeværende år
H83: 0 | I83: Dette skal indtastes jf. kørselsregnskab forrige måned i indeværende år
C85: (Erhvervsmæssigt) Antal kørte kilometer i denne måned | H85: =SUM(#REF!) -> #REF! | I85: Beregnes automatisk
C87: Sum antal kørte kilometer erhvervsmæssigt hele året (inkl. denne måned) | H87: =H83+H85 -> #REF! | I87: Beregnes automatisk
C89: Kørte kilometer i denne måned (hvor samlet sum af kørte kilometer i året er under 20.000) | H89: =IF(H87<=20000,H85,IF(H83>20000,0,20000-H83)) -> #REF! | I89: Beregnes automatisk
C91: Kørte kilometer i denne måned (hvor samlet sum af kørte kilometer i året er over 20.000) | H91: =IF(H87>20000,H87-H83-H89,0) -> #REF! | I91: Beregnes automatisk
C93: Fradrag/ godtgørelse pr. km. | D93: 3.79 | E93: (Kørsel til og med 20.000 km. I året, jf. Skattestyrelsens satser for befordringsgodtgørelse i 2021)
D94: 2.23 | E94: (Kørsel udover 20.000 km. I året, jf. Skattestyrelsens sats for befordringsgodtgørelse i 2021)
C96: Kørselsfradrag/kørselsgodtgørelse i perioden: | G96: =(H89*D93)+(H91*D94) -> #REF! | I96: Beregnes automatisk
C98: Godkendt af (underskrift eller stempel)
C100: Dato

Sheet Kørselsgodtgørelse Feb 2025
B7: Skabelon til kørselsgodtgørelse er fra Dinero Regnskabsprogram
B9: Periode | C9: 45689 | H9: Medarbejderens navn | J9: Sven Arnarsson
B10: Nummerplade | C10: CM73464 | H10: Medarbejderens CPR-nummer | J10: 0411883183
J11: Samlet km | K11: =SUM(L18:L35) -> 826 | N11: d
J12: Sats | K12: 3.81
A13: https://dinero.dk/support/kilometergodtgoerelse/ | J13: Total | K13: =SUM(K11*K12) -> 3147.06
B14: Kørselsregnskab
B16: Dato (skal altid udfyldes) | C16: Beskrivelse (udfyld ved erhverv) | D16: Formålet for kørsel (sæt 1) | F16: Fra (udfyld ved erhverv) | H16: Til (udfyld ved erhverv) | J16: Kilometertæller
D17: Erhverv | E17: Privat | F17: Vejnavn og nr. | G17: Postnummer | H17: Vejnavn og nr. | I17: Postnummer | J17: Frem | K17: Tilbage | L17: Erhverv | M17: Privat
B18: 45691 | C18: Talent garden | D18: 1 | F18: Platanvej 7 | G18: 2791 | H18: Danneskiold-Samsøes Allé 41 | I18: 1434 | J18: 19 | K18: 19 | L18: =SUM(J18:K18) -> 38
